Workbook
Name UPDATE: 'Data Sheet'!$E$1

Sheet Teaser
C3: ITC LTD - ONE PAGER PROFILE
E4: Established in 1910, ITC is the largest cigarette manufacturer and seller in the country. ITC operates in four business segments at present FMCG Cigarettes, FMCG Others, Paperboards, Paper and Packaging, and Agri Business.
B7: KEY FINANCIALS METRICS | D7: 46100 | E7: 46101 | F7: 46102 | G7: 46103 | H7: 46104 | J7: Share Price-5 YEAR
B9: Total Sales | D9: ='Profit-Loss'!E4 -> 48339.58 | E9: ='Profit-Loss'!F4 -> 49387.7 | F9: ='Profit-Loss'!G4 -> 49257.45 | G9: ='Profit-Loss'!H4 -> 60644.54 | H9: ='Profit-Loss'!I4 -> 70919.03
B10: Sales-Growth(y-o-y) | D10: ='Data Sheet'!E34 -> 0.11256063 | E10: ='Data Sheet'!F34 -> 0.021682439 | F10: ='Data Sheet'!G34 -> -0.0026372963 | G10: ='Data Sheet'!H34 -> 0.23117498 | H10: ='Data Sheet'!I34 -> 0.16942152
B11: Gross Profit Margin | D11: ='Profit-Loss'!E30 -> 0.57706604 | E11: ='Profit-Loss'!F30 -> 0.5658662 | F11: ='Profit-Loss'!G30 -> 0.51867748 | G11: ='Profit-Loss'!H30 -> 0.49650026 | H11: ='Profit-Loss'!I30 -> 0.53068887
B12: EBITDA Margins | D12: ='Profit-Loss'!E31 -> 0.38348265 | E12: ='Profit-Loss'!F31 -> 0.39166716 | F12: ='Profit-Loss'!G31 -> 0.34644059 | G12: ='Profit-Loss'!H31 -> 0.34006606 | H12: ='Profit-Loss'!I31 -> 0.36244517
B13: EBIT Margins | D13: ='Profit-Loss'!E33 -> 0.354591 | E13: ='Profit-Loss'!F33 -> 0.35836109 | F13: ='Profit-Loss'!G33 -> 0.31303265 | G13: ='Profit-Loss'!H33 -> 0.31149944 | H13: ='Profit-Loss'!I33 -> 0.33693707
B14: Net Margins | D14: ='Profit-Loss'!E34 -> 0.2604973 | E14: ='Profit-Loss'!F34 -> 0.30991988 | F14: ='Profit-Loss'!G34 -> 0.26719187 | G14: ='Profit-Loss'!H34 -> 0.25134431 | H14: ='Profit-Loss'!I34 -> 0.27061368
B15: EPS | D15: ='Profit-Loss'!E13 -> 10.272242 | E15: ='Profit-Loss'!F13 -> 12.451986 | F15: ='Profit-Loss'!G13 -> 10.692505 | G15: ='Profit-Loss'!H13 -> 12.368976 | H15: ='Profit-Loss'!I13 -> 15.442276
B16: EPS Growth (Y-O-Y ) | D16: ='Profit-Loss'!E35 -> 0.11226415 | E16: ='Profit-Loss'!F35 -> 0.21219753 | F16: ='Profit-Loss'!G35 -> -0.14130126 | G16: ='Profit-Loss'!H35 -> 0.15678939 | H16: ='Profit-Loss'!I35 -> 0.2484684
B17: Dividend Per Share | D17: ='Profit-Loss'!B36 -> 5.6666667 | E17: ='Profit-Loss'!C36 -> 4.5085992 | F17: ='Profit-Loss'!D36 -> 5.1499963 | G17: ='Profit-Loss'!E36 -> 5.7500041 | H17: ='Profit-Loss'!F36 -> 10.149998
B18: Dividend Growth(Y-O-Y ) | D18: ='Profit-Loss'!E37 -> 0.11650645 | E18: ='Profit-Loss'!F37 -> 0.76521571 | F18: ='Profit-Loss'!G37 -> 0.059113555 | G18: ='Profit-Loss'!H37 -> 0.069767819 | H18: ='Profit-Loss'!I37 -> 0.34782561
B20: KEY FINANCIALS RATIO | D20: 46100 | E20: 46101 | F20: 46102 | G20: 46103 | H20: 46104 | J20: Financial Ratios
B22: Price-to-Earnings | D22: ='Profit-Loss'!D14 -> 25.93273 | E22: ='Profit-Loss'!E14 -> 27.12553 | F22: ='Profit-Loss'!F14 -> 12.925649 | G22: ='Profit-Loss'!G14 -> 19.155475 | H22: ='Profit-Loss'!H14 -> 18.995914
B23: EV/EBIT | D23: ='Profit-Loss'!E45 -> 18.215673 | E23: ='Profit-Loss'!F45 -> 9.8674627 | F23: ='Profit-Loss'!G45 -> 14.518397 | G23: ='Profit-Loss'!H45 -> 13.828071 | H23: ='Profit-Loss'!I45 -> 17.191469
B24: EV/SALES | D24: ='Profit-Loss'!E46 -> 6.9853946 | E24: ='Profit-Loss'!F46 -> 3.864761 | F24: ='Profit-Loss'!G46 -> 5.029762 | G24: ='Profit-Loss'!H46 -> 4.7024576 | H24: ='Profit-Loss'!I46 -> 6.2309648
B25: Price-to-book value | D25: ='Profit-Loss'!E48 -> 5.7755936 | E25: ='Profit-Loss'!F48 -> 3.0309955 | F25: ='Profit-Loss'!G48 -> 4.1776297 | G25: ='Profit-Loss'!H48 -> 4.6360678 | H25: ='Profit-Loss'!I48 -> 6.460451
B26: Return-on-equity | D26: ='Balance Sheet'!E23 -> 0.21292095 | E26: ='Balance Sheet'!F23 -> 0.23449465 | F26: ='Balance Sheet'!G23 -> 0.21809064 | G26: ='Balance Sheet'!H23 -> 0.24405605 | H26: ='Balance Sheet'!I23 -> 0.27751555
B27: Return-on-capital employed | D27: ='Balance Sheet'!E24 -> 0.34415688 | E27: ='Balance Sheet'!F24 -> 0.32261652 | F27: ='Balance Sheet'!G24 -> 0.28527066 | G27: ='Balance Sheet'!H24 -> 0.33733253 | H27: ='Balance Sheet'!I24 -> 0.39333609
B30: Shareholders of ITC LTD | C30: % of holding | D30: Shares Held | E30: Value | G30: Shareholding Pattern
B32: British American Tobacco p.l.c. | C32: 0.1902 | D32: 2383450753 | E32: 738154698
B33: Life Insurance Corporation of India | C33: 0.155 | D33: 1941750542 | E33: 601360143
B34: Specified Undertaking of the Unit Trust of India | C34: 0.0778 | D34: 974531427 | E34: 301812383
B35: Myddleton Investment Co. Ltd. | C35: 0.0388 | D35: 486311940 | E35: 150610808
B36: ICICI Prudential Asset Management Company Limited | C36: 0.0313 | D36: 392546212 | E36: 121571562
B37: GQG Partners LLC | C37: 0.0308 | D37: 385750391 | E37: 119466896
B38: Qib Insurance Company | C38: 0.0251 | D38: 313942371 | E38: 97227952
B39: GIC Asset Management Company Ltd. | C39: 0.0173 | D39: 216985508 | E39: 67200412
B40: Nippon Life India Asset Management Limited | C40: 0.0145 | D40: 181206948 | E40: 56119792
B43: Managerial Rumuneration | C43: Designation | D43: Rumuneration | E43: X of Median Salary | G43: Capital Structure
B45: MR.Sanjeev Puri | C45: CMD | D45: 2566 | E45: 377:1 | G45: Enterprise Value | J45: =WACC!E41+WACC!D50 -> 232273.52
B46: S.Dutta | C46: Executive Director | D46: 853 | E46: 132:1 | G46: Add-Cash | J46: ='Data Sheet'!J69 -> 7217.68
B47: H.Malik | C47: Executive Director | D47: 494 | E47: 99:1 | G47: Less-Debt | J47: =WACC!D23 -> 500
B48: B.Sumanth | C48: Executive Director | D48: 1181.4 | E48: 174:1 | G48: Equity Value | J48: =J45+J46-J47 -> 238991.2
G51: Implied Price | J51: =Teaser!J45/'Data Sheet'!B6 -> 185.38532
G52: Current Price | J52: ='Data Sheet'!B8 -> 309.7
G53: Upside/Downside | J53: =(J51-J52)/J52 -> -0.40140354
G54: Conclusion | J54: Overvalued

Sheet WACC
A4: Adjusted Beta | B4: 0.52
B8: Cost Of Debt | J8: Cost of Equity
B10: Pre-Tax Cost of Debt | E10: 0.075 | J10: Risk -Free Rate | M10: 0.07
B11: Tax-Rate | E11: 0.2517 | J11: Market Return | M11: 0.08
B12: Post-Tax Cost of Debt | E12: =E10*(1-E11) -> 0.0561225 | J12: Beta | M12: =B4 -> 0.52
J14: Cost of Equity | M14: =M10+(M12*M11) -> 0.1116
B20: Capital Structure | J20: Weighted Average Cost of Capital
E22: Current | G22: Target | J22: Cost of Equity | M22: =M14 -> 0.1116
B23: Total-Debt | D23: 500 | E23: =D23/D25 -> 0.00097847358 | G23: 0.05 | J23: Equity-weight | M23: =G24 -> 0.95
B24: Market Captilization | D24: 510500 | E24: =E25-E23 -> 0.99902153 | G24: =G25-G23 -> 0.95
B25: Total-Captilization | D25: =SUM(D23:D24) -> 511000 | E25: 1 | G25: 1 | J25: Cost of Debt | M25: =E12 -> 0.0561225
J26: Debt-weight | M26: =G23 -> 0.05
B27: Debt/Equity | E27: =E23/E24 -> 0.00097943193 | G27: =G23/G24 -> 0.052631579
J29: WACC | M29: =(M22*M23)+(M25*M26) -> 0.10882613
B34: FCFF | J34: Reinvestment Ratio
B36: EBIT | E36: ='Profit-Loss'!K32 -> 24193.13 | J36: Growth-Rate | L36: 0.12
B37: Tax-Rate | E37: =E11 -> 0.2517 | J37: EBIT | L37: =E36 -> 24193.13
B38: Growth-Rate | E38: =L36 -> 0.12 | J38: Tax-Rate | L38: =E37 -> 0.2517
B39: Reinvestment Rate | E39: =E38/L43 -> 0.44933963 | J39: Book-Equity | L39: =SUM('Data Sheet'!J57:J58) -> 74507
B40: FCFF | E40: =E36* (1-E37)*(1-E39) -> 9969.0008 | J40: Debt | L40: =D23 -> 500
B41: PV-FCFF | E41: =SUM(L63:P63) -> 54095.45 | J41: Cash | L41: ='Data Sheet'!J69 -> 7217.68
J42: Invested Capital | L42: =L40+L39-L41 -> 67789.32
J43: ROIC | L43: =L37*(1-L38)/L42 -> 0.26705857
B44: Terminal Value
B46: FCFF | D46: =P62 -> 17568.786
B47: WACC | D47: =M29 -> 0.10882613
B48: Growth-rate | D48: 0.05
B49: Terminal Value | D49: =D46/ (D47-D48) -> 298656.18
B50: PV-Terminal Value | D50: =D49/POWER(1+D47,5) -> 178178.07
J60: YEARS | L60: 2025 | M60: 2026 | N60: 2027 | O60: 2028 | P60: 2029
J61: Period | L61: 0.5 | M61: 1.5 | N61: 2.5 | O61: 3.5 | P61: 4.5
J62: FCFF | L62: =E40+(E40*L36) -> 11165.281 | M62: =L62*1.12 -> 12505.115 | N62: =M62*1.12 -> 14005.728 | O62: =N62*1.12 -> 15686.416 | P62: =O62*1.12 -> 17568.786
J63: PV Factor | L63: =L62/ POWER(1+$M$29,L61) -> 10603.224 | M63: =M62/ POWER(1+$M$29,M61) -> 10710.075 | N63: =N62/ POWER(1+$M$29,N61) -> 10818.002 | O63: =O62/ POWER(1+$M$29,O61) -> 10927.018 | P63: =P62/ POWER(1+$M$29,P61) -> 11037.132

Sheet ADJ DATA 
B4: Date | C4: Adj. Close | D4: Stock Return | F4: Adj. Close | G4: Nifty Return
B5: 46082 | C5: 309.7 | F5: 54.84
B6: 46054 | C6: 313.6 | D6: =C6/C5-1 -> 0.012592832 | F6: 57.21 | G6: =F6/F5-1 -> 0.04321663
B7: 46023 | C7: 315.54 | D7: =C7/C6-1 -> 0.0061862245 | F7: 56.21 | G7: =F7/F6-1 -> -0.017479462 | I7: =SLOPE(D6:D124,G6:G124) -> 0.30044101
B8: 45992 | C8: 394.73 | D8: =C8/C7-1 -> 0.2509666 | F8: 58.32 | G8: =F8/F7-1 -> 0.037537805
B9: 45962 | C9: 395.95 | D9: =C9/C8-1 -> 0.0030907202 | F9: 58.55 | G9: =F9/F8-1 -> 0.0039437586 | I9: Adjusted Beta
B10: 45931 | C10: 411.72 | D10: =C10/C9-1 -> 0.039828261 | F10: 58.02 | G10: =F10/F9-1 -> -0.0090520922 | I10: =0.63*I7+0.33*1 -> 0.51927784
B11: 45901 | C11: 393.31 | D11: =C11/C10-1 -> -0.044714855 | F11: 56.21 | G11: =F11/F10-1 -> -0.031196139
B12: 45870 | C12: 401.34 | D12: =C12/C11-1 -> 0.020416465 | F12: 56.15 | G12: =F12/F11-1 -> -0.0010674257
B13: 45839 | C13: 403.49 | D13: =C13/C12-1 -> 0.0053570539 | F13: 56.1 | G13: =F13/F12-1 -> -0.00089047195
B14: 45809 | C14: 407.9 | D14: =C14/C13-1 -> 0.010929639 | F14: 59.23 | G14: =F14/F13-1 -> 0.055793226
B15: 45778 | C15: 409.47 | D15: =C15/C14-1 -> 0.0038489826 | F15: 57.76 | G15: =F15/F14-1 -> -0.024818504
B16: 45748 | C16: 409.51 | D16: =C16/C15-1 -> 9.7687254e-05 | F16: 57.05 | G16: =F16/F15-1 -> -0.012292244
B17: 45717 | C17: 394.08 | D17: =C17/C16-1 -> -0.037679178 | F17: 55.07 | G17: =F17/F16-1 -> -0.034706398
B18: 45689 | C18: 379.89 | D18: =C18/C17-1 -> -0.036007917 | F18: 51.37 | G18: =F18/F17-1 -> -0.067187216
B19: 45658 | C19: 423.7 | D19: =C19/C18-1 -> 0.11532286 | F19: 54.57 | G19: =F19/F18-1 -> 0.062293167
B20: 45627 | C20: 440.81 | D20: =C20/C19-1 -> 0.040382346 | F20: 55.3 | G20: =F20/F19-1 -> 0.013377314
B21: 45597 | C21: 434.52 | D21: =C21/C20-1 -> -0.014269186 | F21: 57.34 | G21: =F21/F20-1 -> 0.036889693
B22: 45566 | C22: 445.5 | D22: =C22/C21-1 -> 0.025269263 | F22: 58.78 | G22: =F22/F21-1 -> 0.025113359
... B124: 42461 | C124: 147.29 | D124: =C124/C123-1 -> -0.096269481 | F124: 57.89 | G124: =F124/F123-1 -> -0.0066918325
B129: Cost Of Debt | C129: =0.11*(1-0.25) -> 0.0825
B130: Cost of Equity | C130: =0.0739+0.52*0.08 -> 0.1155 | E130: WACC | F130: =C130*C134+ (C129*C135) -> 0.11548405
B131: Market Captilization | C131: ='Profit-Loss'!K40 -> 512765.25
B132: Debt | C132: 248
B133: TOTAL CAPITAL | C133: =SUM(C131:C132) -> 513013.25
B134: EQUITY-FUNDING | C134: =C131/C133 -> 0.99951658
B135: Debt-Funding | C135: =C132/C133 -> 0.00048341832

Sheet Data Sheet
A1: COMPANY NAME | B1: ITC LTD | E1: =IF(B2<>B3, "A NEW VERSION OF THE WORKSHEET IS AVAILABLE", "")
A2: LATEST VERSION | B2: 2.1 | E2: PLEASE DO NOT MAKE ANY CHANGES TO THIS SHEET
A3: CURRENT VERSION | B3: 2.1
A5: META
A6: Number of shares | B6: =IF(B9>0, B9/B8, 0) -> 1252.9229
A7: Face Value | B7: 1
A8: Current Price | B8: 309.7
A9: Market Capitalization | B9: 388030.23
A15: PROFIT & LOSS
A16: Report Date | B16: 42460 | C16: 42825 | D16: 43190 | E16: 43555 | F16: 43921 | G16: 44286 | H16: 44651 | I16: 45016 | J16: 45382 | K16: 45747
A17: Sales | B17: 39192.1 | C17: 42767.6 | D17: 43448.94 | E17: 48339.58 | F17: 49387.7 | G17: 49257.45 | H17: 60644.54 | I17: 70919.03 | J17: 67931.94 | K17: 75323.34
A18: Raw Material Cost | B18: 13763.88 | C18: 15456.59 | D18: 14827.72 | E18: 17623.52 | F18: 18048.6 | G18: 20776.71 | H18: 27071.07 | I18: 29364.36 | J18: 27348.57 | K18: 32704.37
A19: Change in Inventory | B19: 195.38 | C19: -592.57 | D19: -1027.76 | E19: 203.19 | F19: 703.13 | G19: 645.27 | H19: 686 | I19: 358.59 | J19: 367.77 | K19: 725.65
A20: Power and Fuel | B20: 571.88 | C20: 584.33 | D20: 653.5 | E20: 746.73 | F20: 780.85 | G20: 699.56 | H20: 889.77 | I20: 1232.34 | J20: 952.9 | K20: 975.35
A21: Other Mfr. Exp | B21: 1581.59 | C21: 1683.9 | D21: 1697.62 | E21: 1871.01 | F21: 1908.29 | G21: 1587.18 | H21: 1887.67 | I21: 2327.8 | J21: 2183.76 | K21: 2345.36
A22: Employee Cost | B22: 3440.97 | C22: 3631.73 | D22: 3760.9 | E22: 4177.88 | F22: 4295.79 | G22: 4463.33 | H22: 4890.55 | I22: 5736.22 | J22: 5548.53 | K22: 6169.78
A23: Selling and admin | B23: 4261.78 | C23: 4179.74 | D23: 3954.87 | E23: 4546.39 | F23: 4488.63 | G23: 4236.77 | H23: 4858.38 | I23: 5604.08 | J23: 5312.45 | K23: 5793.29
A24: Other Expenses | B24: 1235.89 | C24: 1169.23 | D24: 1005.98 | E24: 1039.85 | F24: 1225.13 | G24: 1074.39 | H24: 1109.95 | I24: 1308.56 | J24: 1765.97 | K24: 2221.39
A25: Other Income | B25: 1483.11 | C25: 1758.63 | D25: 2239.81 | E25: 2080.44 | F25: 2417.32 | G25: 2576.95 | H25: 1909.72 | I25: 2097.64 | J25: 3330.45 | K25: 17794.88
A26: Depreciation | B26: 1077.4 | C26: 1152.79 | D26: 1236.28 | E26: 1396.61 | F26: 1644.91 | G26: 1645.59 | H26: 1732.41 | I26: 1809.01 | J26: 1518.05 | K26: 1646.32
A27: Interest | B27: 78.13 | C27: 49.03 | D27: 115.01 | E27: 71.4 | F27: 81.38 | G27: 57.97 | H27: 59.99 | I27: 77.77 | J27: 39.11 | K27: 45.06
... A31: Dividend Amount | B31: 6840.12 | C31: 5770.02 | D31: 6285.21 | E31: 7048.7 | F31: 12476.58 | G31: 13231.96 | H31: 14171.8 | I31: 19263.4 | J31: 17166.46 | K31: 17957.73
A34: sales-growth | C34: =C17/B17-1 -> 0.09123012 | D34: =D17/C17-1 -> 0.015931219 | E34: =E17/D17-1 -> 0.11256063 | F34: =F17/E17-1 -> 0.021682439 | G34: =G17/F17-1 -> -0.0026372963 | H34: =H17/G17-1 -> 0.23117498 | I34: =I17/H17-1 -> 0.16942152 | J34: =J17/I17-1 -> -0.042119724 | K34: =K17/J17-1 -> 0.10880596
A40: Quarters
A41: Report Date | B41: 45199 | C41: 45291 | D41: 45382 | E41: 45473 | F41: 45565 | G41: 45657 | H41: 45747 | I41: 45838 | J41: 45930 | K41: 46022
A42: Sales | B42: 17774.47 | C42: 17195.24 | D42: 17037.8 | E42: 17777.81 | F42: 19990.36 | G42: 18790.17 | H42: 18765 | I42: 21494.79 | J42: 19501.63 | K42: 20047.3
A43: Expenses | B43: 11320.23 | C43: 10985.01 | D43: 10735.73 | E43: 11232.97 | F43: 13438.28 | G43: 12428.27 | H43: 12245.61 | I43: 14678.32 | J43: 12806.94 | K43: 13164.78
A44: Other Income | B44: 673.5 | C44: 820.26 | D44: 868 | E44: 771.13 | F44: 690.31 | G44: 803.4 | H44: 15391.28 | I44: 750.97 | J44: 738.84 | K44: 321.85
A45: Depreciation | B45: 453.04 | C45: 384.04 | D45: 385.09 | E45: 403.13 | F45: 416.18 | G45: 415.98 | H45: 411.03 | I45: 422.96 | J45: 434.8 | K45: 430.82
A46: Interest | B46: 9.87 | C46: 11.94 | D46: 10.72 | E46: 9.6 | F46: 14.73 | G46: 9.82 | H46: 10.91 | I46: 16.47 | J46: 20.05 | K46: 19.47
A47: Profit before tax | B47: 6664.83 | C47: 6634.51 | D47: 6774.26 | E47: 6903.24 | F47: 6811.48 | G47: 6739.5 | H47: 21488.73 | I47: 7128.01 | J47: 6978.68 | K47: 6754.08
A48: Tax | B48: 1700.31 | C48: 1227.99 | D48: 1583.55 | E48: 1726.25 | F48: 1757.05 | G48: 1726.32 | H48: 1680.85 | I48: 1784.6 | J48: 1792.13 | K48: 1735.63
A49: Net profit | B49: 4898.07 | C49: 5335.23 | D49: 5120.55 | E49: 5091.59 | F49: 4992.87 | G49: 4934.8 | H49: 19727.37 | I49: 5244.2 | J49: 5126.11 | K49: 4931.19
A50: Operating Profit | B50: 6454.24 | C50: 6210.23 | D50: 6302.07 | E50: 6544.84 | F50: 6552.08 | G50: 6361.9 | H50: 6519.39 | I50: 6816.47 | J50: 6694.69 | K50: 6882.52
A55: BALANCE SHEET
A56: Report Date | B56: 42460 | C56: 42825 | D56: 43190 | E56: 43555 | F56: 43921 | G56: 44286 | H56: 44651 | I56: 45016 | J56: 45382 | K56: 45747
A57: Equity Share Capital | B57: 804.72 | C57: 1214.74 | D57: 1220.43 | E57: 1225.86 | F57: 1229.22 | G57: 1230.88 | H57: 1232.33 | I57: 1242.8 | J57: 1248.47 | K57: 1251.41
A58: Reserves | B58: 41874.8 | C58: 45198.19 | D58: 51289.68 | E58: 57915.01 | F58: 64044.04 | G58: 59116.46 | H58: 61223.24 | I58: 67912.46 | J58: 73258.53 | K58: 68778.64
A59: Borrowings | B59: 83.78 | C59: 45.72 | D59: 35.92 | E59: 13.44 | F59: 277.45 | G59: 270.83 | H59: 249.44 | I59: 306.04 | J59: 303.43 | K59: 284.54
A60: Other Liabilities | B60: 8888.04 | C60: 9439.67 | D60: 11694.85 | E60: 12584.73 | F60: 11760.04 | G60: 13142.59 | H60: 14491.01 | I60: 16369.66 | J60: 16943.54 | K60: 17688.11
...

Sheet Profit-Loss
A1: ='Data Sheet'!B1 -> ITC LTD | H1: =UPDATE | M1: SCREENER.IN
A3: Narration | B3: ='Data Sheet'!B16 -> 42460 | C3: ='Data Sheet'!C16 -> 42825 | D3: ='Data Sheet'!D16 -> 43190 | E3: ='Data Sheet'!E16 -> 43555 | F3: ='Data Sheet'!F16 -> 43921 | G3: ='Data Sheet'!G16 -> 44286 | H3: ='Data Sheet'!H16 -> 44651 | I3: ='Data Sheet'!I16 -> 45016 | ... K3: ='Data Sheet'!K16 -> 45747 | L3: Trailing | M3: Best Case | N3: Worst Case
A4: Sales | B4: ='Data Sheet'!B17 -> 39192.1 | C4: ='Data Sheet'!C17 -> 42767.6 | D4: ='Data Sheet'!D17 -> 43448.94 | E4: ='Data Sheet'!E17 -> 48339.58 | F4: ='Data Sheet'!F17 -> 49387.7 | G4: ='Data Sheet'!G17 -> 49257.45 | H4: ='Data Sheet'!H17 -> 60644.54 | I4: ='Data Sheet'!I17 -> 70919.03 | ... K4: ='Data Sheet'!K17 -> 75323.34 | L4: =SUM(Quarters!H4:K4) -> 79808.72 | M4: =$K4+M23*K4 -> 83518.968 | N4: =$K4+N23*L4 -> 81303.23
A5: Expenses | B5: =SUM('Data Sheet'!B18,'Data Sheet'!B20:B24, -1*'Data Sheet'!B19) -> 24660.61 | C5: =SUM('Data Sheet'!C18,'Data Sheet'!C20:C24, -1*'Data Sheet'!C19) -> 27298.09 | D5: =SUM('Data Sheet'!D18,'Data Sheet'!D20:D24, -1*'Data Sheet'!D19) -> 26928.35 | E5: =SUM('Data Sheet'!E18,'Data Sheet'!E20:E24, -1*'Data Sheet'!E19) -> 29802.19 | F5: =SUM('Data Sheet'!F18,'Data Sheet'!F20:F24, -1*'Data Sheet'!F19) -> 30044.16 | G5: =SUM('Data Sheet'!G18,'Data Sheet'!G20:G24, -1*'Data Sheet'!G19) -> 32192.67 | H5: =SUM('Data Sheet'!H18,'Data Sheet'!H20:H24, -1*'Data Sheet'!H19) -> 40021.39 | I5: =SUM('Data Sheet'!I18,'Data Sheet'!I20:I24, -1*'Data Sheet'!I19) -> 45214.77 | ... K5: =SUM('Data Sheet'!K18,'Data Sheet'!K20:K24, -1*'Data Sheet'!K19) -> 49483.89 | L5: =SUM(Quarters!H5:K5) -> 52895.65 | M5: =M4-M6 -> 53597.014 | N5: =N4-N6 -> 53886.182
A6: Operating Profit | B6: =B4-B5 -> 14531.49 | C6: =C4-C5 -> 15469.51 | D6: =D4-D5 -> 16520.59 | E6: =E4-E5 -> 18537.39 | F6: =F4-F5 -> 19343.54 | G6: =G4-G5 -> 17064.78 | H6: =H4-H5 -> 20623.15 | I6: =I4-I5 -> 25704.26 | ... K6: =K4-K5 -> 25839.45 | L6: =SUM(Quarters!H6:K6) -> 26913.07 | M6: =M4*M24 -> 29921.955 | N6: =N4*N24 -> 27417.048
A7: Other Income | B7: ='Data Sheet'!B25 -> 1483.11 | C7: ='Data Sheet'!C25 -> 1758.63 | D7: ='Data Sheet'!D25 -> 2239.81 | E7: ='Data Sheet'!E25 -> 2080.44 | F7: ='Data Sheet'!F25 -> 2417.32 | G7: ='Data Sheet'!G25 -> 2576.95 | H7: ='Data Sheet'!H25 -> 1909.72 | I7: ='Data Sheet'!I25 -> 2097.64 | ... K7: ='Data Sheet'!K25 -> 17794.88 | L7: =SUM(Quarters!H7:K7) -> 17202.94 | M7: 0 | N7: 0
A8: Depreciation | B8: ='Data Sheet'!B26 -> 1077.4 | C8: ='Data Sheet'!C26 -> 1152.79 | D8: ='Data Sheet'!D26 -> 1236.28 | E8: ='Data Sheet'!E26 -> 1396.61 | F8: ='Data Sheet'!F26 -> 1644.91 | G8: ='Data Sheet'!G26 -> 1645.59 | H8: ='Data Sheet'!H26 -> 1732.41 | I8: ='Data Sheet'!I26 -> 1809.01 | ... K8: ='Data Sheet'!K26 -> 1646.32 | L8: =SUM(Quarters!H8:K8) -> 1699.61 | M8: =+$L8 -> 1699.61 | N8: =+$L8 -> 1699.61
A9: Interest | B9: ='Data Sheet'!B27 -> 78.13 | C9: ='Data Sheet'!C27 -> 49.03 | D9: ='Data Sheet'!D27 -> 115.01 | E9: ='Data Sheet'!E27 -> 71.4 | F9: ='Data Sheet'!F27 -> 81.38 | G9: ='Data Sheet'!G27 -> 57.97 | H9: ='Data Sheet'!H27 -> 59.99 | I9: ='Data Sheet'!I27 -> 77.77 | ... K9: ='Data Sheet'!K27 -> 45.06 | L9: =SUM(Quarters!H9:K9) -> 66.9 | M9: =+$L9 -> 66.9 | N9: =+$L9 -> 66.9
A10: Profit before tax | B10: ='Data Sheet'!B28 -> 14859.07 | C10: ='Data Sheet'!C28 -> 16026.32 | D10: ='Data Sheet'!D28 -> 17409.11 | E10: ='Data Sheet'!E28 -> 19149.82 | F10: ='Data Sheet'!F28 -> 20034.57 | G10: ='Data Sheet'!G28 -> 17938.17 | H10: ='Data Sheet'!H28 -> 20740.47 | I10: ='Data Sheet'!I28 -> 25915.12 | ... K10: ='Data Sheet'!K28 -> 41942.95 | L10: =SUM(Quarters!H10:K10) -> 42349.5 | M10: =M6+M7-SUM(M8:M9) -> 28155.445 | N10: =N6+N7-SUM(N8:N9) -> 25650.538
A11: Tax | B11: ='Data Sheet'!B29 -> 5358.21 | C11: ='Data Sheet'!C29 -> 5549.09 | D11: ='Data Sheet'!D29 -> 5916.43 | E11: ='Data Sheet'!E29 -> 6313.92 | F11: ='Data Sheet'!F29 -> 4441.79 | G11: ='Data Sheet'!G29 -> 4555.29 | H11: ='Data Sheet'!H29 -> 5237.34 | I11: ='Data Sheet'!I29 -> 6438.4 | ... K11: ='Data Sheet'!K29 -> 6890.47 | L11: =SUM(Quarters!H11:K11) -> 6993.21 | M11: =IF($L10>0,$L11/$L10,0) -> 0.16513088 | N11: =IF($L10>0,$L11/$L10,0) -> 0.16513088
A12: Net profit | B12: ='Data Sheet'!B30 -> 9344.45 | C12: ='Data Sheet'!C30 -> 10289.44 | D12: ='Data Sheet'!D30 -> 11271.2 | E12: ='Data Sheet'!E30 -> 12592.33 | F12: ='Data Sheet'!F30 -> 15306.23 | G12: ='Data Sheet'!G30 -> 13161.19 | H12: ='Data Sheet'!H30 -> 15242.66 | I12: ='Data Sheet'!I30 -> 19191.66 | ... K12: ='Data Sheet'!K30 -> 34746.63 | L12: =SUM(Quarters!H12:K12) -> 35028.87 | M12: =M10-M11*M10 -> 23506.111 | N12: =N10-N11*N10 -> 21414.842
A13: EPS | B13: =IF('Data Sheet'!B93>0,B12/'Data Sheet'!B93,0) -> 7.7413676 | C13: 8.04 | D13: =IF('Data Sheet'!D93>0,D12/'Data Sheet'!D93,0) -> 9.2354334 | E13: =IF('Data Sheet'!E93>0,E12/'Data Sheet'!E93,0) -> 10.272242 | F13: =IF('Data Sheet'!F93>0,F12/'Data Sheet'!F93,0) -> 12.451986 | G13: =IF('Data Sheet'!G93>0,G12/'Data Sheet'!G93,0) -> 10.692505 | H13: =IF('Data Sheet'!H93>0,H12/'Data Sheet'!H93,0) -> 12.368976 | I13: =IF('Data Sheet'!I93>0,I12/'Data Sheet'!I93,0) -> 15.442276 | J13: =IF('Data Sheet'!J93>0,J12/'Data Sheet'!J93,0) -> 16.387082 | K13: =IF('Data Sheet'!K93>0,K12/'Data Sheet'!K93,0) -> 27.765984 | L13: =IF('Data Sheet'!$B6>0,'Profit-Loss'!L12/'Data Sheet'!$B6,0) -> 27.957721 | M13: =IF('Data Sheet'!$B6>0,'Profit-Loss'!M12/'Data Sheet'!$B6,0) -> 18.76102 | N13: =IF('Data Sheet'!$B6>0,'Profit-Loss'!N12/'Data Sheet'!$B6,0) -> 17.091907
A14: Price to earning | B14: =IF(B15>0,B15/B13,"") -> 26.497902 | C14: =IF(C15>0,C15/C13,"") -> 32.680348 | D14: =IF(D15>0,D15/D13,"") -> 25.93273 | E14: =IF(E15>0,E15/E13,"") -> 27.12553 | F14: =IF(F15>0,F15/F13,"") -> 12.925649 | G14: =IF(G15>0,G15/G13,"") -> 19.155475 | H14: =IF(H15>0,H15/H13,"") -> 18.995914 | I14: =IF(I15>0,I15/I13,"") -> 23.2796 | ... K14: =IF(K15>0,K15/K13,"") -> 14.757266 | L14: =IF(L13>0,L15/L13,0) -> 11.077441 | M14: =M25 -> 18.404286 | N14: =N25 -> 11.077441
A15: Price | B15: ='Data Sheet'!B90 -> 205.13 | C15: ='Data Sheet'!C90 -> 262.75 | D15: ='Data Sheet'!D90 -> 239.5 | E15: ='Data Sheet'!E90 -> 278.64 | F15: ='Data Sheet'!F90 -> 160.95 | G15: ='Data Sheet'!G90 -> 204.82 | H15: ='Data Sheet'!H90 -> 234.96 | I15: ='Data Sheet'!I90 -> 359.49 | ... K15: ='Data Sheet'!K90 -> 409.75 | L15: ='Data Sheet'!B8 -> 309.7 | M15: =M13*M14 -> 345.28317 | N15: =N13*N14 -> 189.33459
A17: RATIOS:
A18: Dividend Payout | B18: =IF('Data Sheet'!B30>0, 'Data Sheet'!B31/'Data Sheet'!B30, 0) -> 0.73199814 | C18: =IF('Data Sheet'!C30>0, 'Data Sheet'!C31/'Data Sheet'!C30, 0) -> 0.56077104 | D18: =IF('Data Sheet'!D30>0, 'Data Sheet'!D31/'Data Sheet'!D30, 0) -> 0.5576345 | E18: =IF('Data Sheet'!E30>0, 'Data Sheet'!E31/'Data Sheet'!E30, 0) -> 0.55976138 | F18: =IF('Data Sheet'!F30>0, 'Data Sheet'!F31/'Data Sheet'!F30, 0) -> 0.81513083 | G18: =IF('Data Sheet'!G30>0, 'Data Sheet'!G31/'Data Sheet'!G30, 0) -> 1.0053772 | H18: =IF('Data Sheet'!H30>0, 'Data Sheet'!H31/'Data Sheet'!H30, 0) -> 0.92974586 | I18: =IF('Data Sheet'!I30>0, 'Data Sheet'!I31/'Data Sheet'!I30, 0) -> 1.0037381 | ... K18: =IF('Data Sheet'!K30>0, 'Data Sheet'!K31/'Data Sheet'!K30, 0) -> 0.51681933
A19: OPM | B19: =IF(B6>0,B6/B4,0) -> 0.370776 | C19: =IF(C6>0,C6/C4,0) -> 0.36171097 | D19: =IF(D6>0,D6/D4,0) -> 0.38022999 | E19: =IF(E6>0,E6/E4,0) -> 0.38348265 | F19: =IF(F6>0,F6/F4,0) -> 0.39166716 | G19: =IF(G6>0,G6/G4,0) -> 0.34644059 | H19: =IF(H6>0,H6/H4,0) -> 0.34006606 | I19: =IF(I6>0,I6/I4,0) -> 0.36244517 | ... L19: =IF(L6>0,L6/L4,0) -> 0.33721967
G22: TRENDS: | H22: 10 YEARS | I22: 7 YEARS | J22: 5 YEARS | K22: 3 YEARS | L22: RECENT | M22: BEST | N22: WORST
G23: Sales Growth | H23: =IF(B4=0,"",POWER($K4/B4,1/9)-1) -> 0.075290157 | I23: =IF(D4=0,"",POWER($K4/D4,1/7)-1) -> 0.081772082 | J23: =IF(F4=0,"",POWER($K4/F4,1/5)-1) -> 0.088083322 | K23: =IF(H4=0,"",POWER($K4/H4, 1/3)-1) -> 0.074927782 | L23: =IF(ISERROR(MAX(IF(J4=0,"",(K4-J4)/J4),IF(K4=0,"",(L4-K4)/K4))),"",MAX(IF(J4=0,"",(K4-J4)/J4),IF(K4=0,"",(L4-K4)/K4))) -> 0.10880596 | M23: =MAX(K23:L23) -> 0.10880596 | N23: =MIN(H23:L23) -> 0.074927782
G24: OPM | H24: =IF(SUM(B4:$K$4)=0,"",SUMPRODUCT(B19:$K$19,B4:$K$4)/SUM(B4:$K$4)) -> 0.36333562 | I24: =IF(SUM(E4:$K$4)=0,"",SUMPRODUCT(E19:$K$19,E4:$K$4)/SUM(E4:$K$4)) -> 0.36106877 | J24: =IF(SUM(G4:$K$4)=0,"",SUMPRODUCT(G19:$K$19,G4:$K$4)/SUM(G4:$K$4)) -> 0.35306244 | K24: =IF(SUM(I4:$K$4)=0, "", SUMPRODUCT(I19:$K$19,I4:$K$4)/SUM(I4:$K$4)) -> 0.35826538 | L24: =L19 -> 0.33721967 | M24: =MAX(K24:L24) -> 0.35826538 | N24: =MIN(H24:L24) -> 0.33721967
G25: Price to Earning | H25: =IF(ISERROR(AVERAGEIF(B14:$L14,">0")),"",AVERAGEIF(B14:$L14,">0")) -> 21.539154 | I25: =IF(ISERROR(AVERAGEIF(E14:$L14,">0")),"",AVERAGEIF(E14:$L14,">0")) -> 18.977464 | J25: =IF(ISERROR(AVERAGEIF(G14:$L14,">0")),"",AVERAGEIF(G14:$L14,">0")) -> 18.628089 | K25: =IF(ISERROR(AVERAGEIF(I14:$L14,">0")),"",AVERAGEIF(I14:$L14,">0")) -> 18.404286 | L25: =L14 -> 11.077441 | M25: =MAX(K25:L25) -> 18.404286 | N25: =MIN(H25:L25) -> 11.077441
A29: Gross-profit | B29: ='Data Sheet'!B17-'Data Sheet'!B18-'Data Sheet'!B19-'Data Sheet'!B20-'Data Sheet'!B21 -> 23079.37 | C29: ='Data Sheet'!C17-'Data Sheet'!C18-'Data Sheet'!C19-'Data Sheet'!C20-'Data Sheet'!C21 -> 25635.35 | D29: ='Data Sheet'!D17-'Data Sheet'!D18-'Data Sheet'!D19-'Data Sheet'!D20-'Data Sheet'!D21 -> 27297.86 | E29: ='Data Sheet'!E17-'Data Sheet'!E18-'Data Sheet'!E19-'Data Sheet'!E20-'Data Sheet'!E21 -> 27895.13 | F29: ='Data Sheet'!F17-'Data Sheet'!F18-'Data Sheet'!F19-'Data Sheet'!F20-'Data Sheet'!F21 -> 27946.83 | G29: ='Data Sheet'!G17-'Data Sheet'!G18-'Data Sheet'!G19-'Data Sheet'!G20-'Data Sheet'!G21 -> 25548.73 | H29: ='Data Sheet'!H17-'Data Sheet'!H18-'Data Sheet'!H19-'Data Sheet'!H20-'Data Sheet'!H21 -> 30110.03 | I29: ='Data Sheet'!I17-'Data Sheet'!I18-'Data Sheet'!I19-'Data Sheet'!I20-'Data Sheet'!I21 -> 37635.94 | ... K29: ='Data Sheet'!K17-'Data Sheet'!K18-'Data Sheet'!K19-'Data Sheet'!K20-'Data Sheet'!K21 -> 38572.61
A30: GRM | B30: =B29/B4 -> 0.58887812 | C30: =C29/C4 -> 0.59941054 | D30: =D29/D4 -> 0.62827448 | E30: =E29/E4 -> 0.57706604 | F30: =F29/F4 -> 0.5658662 | G30: =G29/G4 -> 0.51867748 | H30: =H29/H4 -> 0.49650026 | I30: =I29/I4 -> 0.53068887 | ... K30: =K29/K4 -> 0.51209373
A31: EBITDA MARGINS | B31: =B6/B4 -> 0.370776 | C31: =C6/C4 -> 0.36171097 | D31: =D6/D4 -> 0.38022999 | E31: =E6/E4 -> 0.38348265 | F31: =F6/F4 -> 0.39166716 | G31: =G6/G4 -> 0.34644059 | H31: =H6/H4 -> 0.34006606 | I31: =I6/I4 -> 0.36244517 | ... K31: =K6/K4 -> 0.34304706
A32: EBIT | B32: =B6-B8 -> 13454.09 | C32: =C6-C8 -> 14316.72 | D32: =D6-D8 -> 15284.31 | E32: =E6-E8 -> 17140.78 | F32: =F6-F8 -> 17698.63 | G32: =G6-G8 -> 15419.19 | H32: =H6-H8 -> 18890.74 | I32: =I6-I8 -> 23895.25 | ... K32: =K6-K8 -> 24193.13
A33: EBIT Margins | B33: =B32/B4 -> 0.34328576 | C33: =C32/C4 -> 0.33475622 | D33: =D32/D4 -> 0.35177636 | E33: =E32/E4 -> 0.354591 | F33: =F32/F4 -> 0.35836109 | G33: =G32/G4 -> 0.31303265 | H33: =H32/H4 -> 0.31149944 | I33: =I32/I4 -> 0.33693707 | ... K33: =K32/K4 -> 0.32119035
A34: Net Profit Margins | B34: =B12/B4 -> 0.23842688 | C34: =C12/C4 -> 0.24058961 | D34: =D12/D4 -> 0.25941254 | E34: =E12/E4 -> 0.2604973 | F34: =F12/F4 -> 0.30991988 | G34: =G12/G4 -> 0.26719187 | H34: =H12/H4 -> 0.25134431 | I34: =I12/I4 -> 0.27061368 | ... K34: =K12/K4 -> 0.46129964
A35: EPS Growth | C35: =C13/B13-1 -> 0.038576182 | D35: =D13/C13-1 -> 0.14868575 | E35: =E13/D13-1 -> 0.11226415 | F35: =F13/E13-1 -> 0.21219753 | G35: =G13/F13-1 -> -0.14130126 | H35: =H13/G13-1 -> 0.15678939 | I35: =I13/H13-1 -> 0.2484684 | J35: =J13/I13-1 -> 0.0611831 | K35: =K13/J13-1 -> 0.69438246
A36: Dividend Per Share | B36: =B13*B18 -> 5.6666667 | C36: =C13*C18 -> 4.5085992 | D36: =D13*D18 -> 5.1499963 | E36: =E13*E18 -> 5.7500041 | F36: =F13*F18 -> 10.149998 | G36: =G13*G18 -> 10.75 | H36: =H13*H18 -> 11.500004 | I36: =I13*I18 -> 15.5 | ... K36: =K13*K18 -> 14.349997
A37: Dividend Growth | C37: =C36/B36-1 -> -0.20436485 | D37: =D36/C36-1 -> 0.14226084 | E37: =E36/D36-1 -> 0.11650645 | F37: =F36/E36-1 -> 0.76521571 | G37: =G36/F36-1 -> 0.059113555 | H37: =H36/G36-1 -> 0.069767819 | I37: =I36/H36-1 -> 0.34782561 | J37: =J36/I36-1 -> -0.11290335 | K37: =K36/J36-1 -> 0.043636312
A40: Market Captilization | B40: ='Data Sheet'!B93*'Data Sheet'!B90 -> 247608.32 | C40: ='Data Sheet'!C93*'Data Sheet'!C90 -> 319172.93 | D40: ='Data Sheet'!D93*'Data Sheet'!D90 -> 292292.99 | E40: ='Data Sheet'!E93*'Data Sheet'!E90 -> 341573.63 | F40: ='Data Sheet'!F93*'Data Sheet'!F90 -> 197842.96 | G40: ='Data Sheet'!G93*'Data Sheet'!G90 -> 252108.84 | H40: ='Data Sheet'!H93*'Data Sheet'!H90 -> 289548.26 | I40: ='Data Sheet'!I93*'Data Sheet'!I90 -> 446774.17 | ... K40: ='Data Sheet'!K93*'Data Sheet'!K90 -> 512765.25
A41: Debt | B41: ='Balance Sheet'!E6 -> 13.44 | C41: ='Balance Sheet'!F6 -> 277.45 | D41: ='Balance Sheet'!G6 -> 270.83 | E41: ='Balance Sheet'!H6 -> 249.44 | F41: ='Balance Sheet'!I6 -> 306.04 | G41: ='Balance Sheet'!J6 -> 303.43 | H41: ='Balance Sheet'!K6 -> 284.54 | I41: ='Balance Sheet'!L6 -> 0 | ... K41: ='Balance Sheet'!N6 -> 0
A42: Cash | B42: ='Data Sheet'!B69 -> 6063.3 | C42: ='Data Sheet'!C69 -> 2967.4 | D42: ='Data Sheet'!D69 -> 2899.6 | E42: ='Data Sheet'!E69 -> 4152.03 | F42: ='Data Sheet'!F69 -> 7277.34 | G42: ='Data Sheet'!G69 -> 4659.02 | H42: ='Data Sheet'!H69 -> 4654.42 | I42: ='Data Sheet'!I69 -> 4880.19 | ... K42: ='Data Sheet'!K69 -> 4012.36
A43: EV | B43: =B40+B41-B42 -> 241558.46 | C43: =C40+C41-C42 -> 316482.98 | D43: =D40+D41-D42 -> 289664.22 | E43: =E40+E41-E42 -> 337671.04 | F43: =F40+F41-F42 -> 190871.66 | G43: =G40+G41-G42 -> 247753.25 | H43: =H40+H41-H42 -> 285178.38 | I43: =I40+I41-I42 -> 441893.98 | ... K43: =K40+K41-K42 -> 508752.89
A45: EV/EBIT | B45: =B43/B6 -> 16.623103 | C45: =C43/C6 -> 20.458501 | D45: =D43/D6 -> 17.533527 | E45: =E43/E6 -> 18.215673 | F45: =F43/F6 -> 9.8674627 | G45: =G43/G6 -> 14.518397 | H45: =H43/H6 -> 13.828071 | I45: =I43/I6 -> 17.191469 | ... K45: =K43/K6 -> 19.688998
A46: EV/SALES | B46: =B43/B4 -> 6.1634477 | C46: =C43/C4 -> 7.4000642 | D46: =D43/D4 -> 6.6667729 | E46: =E43/E4 -> 6.9853946 | F46: =F43/F4 -> 3.864761 | G46: =G43/G4 -> 5.029762 | H46: =H43/H4 -> 4.7024576 | I46: =I43/I4 -> 6.2309648 | ... K46: =K43/K4 -> 6.7542529
A48: p/b | E48: =E40/'Balance Sheet'!E26 -> 5.7755936 | F48: =F40/'Balance Sheet'!F26 -> 3.0309955 | G48: =G40/'Balance Sheet'!G26 -> 4.1776297 | H48: =H40/'Balance Sheet'!H26 -> 4.6360678 | I48: =I40/'Balance Sheet'!I26 -> 6.460451 | J48: =J40/'Balance Sheet'!J26 -> 6.7282022 | K48: =K40/'Balance Sheet'!K26 -> 7.3220746
A50: Fills | B50: 0.3611
A51: Dills | B51: 0.489
A52: Public | B52: 0.1495

Sheet Quarters
A1: ='Profit-Loss'!A1 -> ITC LTD | E1: =UPDATE | J1: SCREENER.IN
A3: Narration | B3: ='Data Sheet'!B41 -> 45199 | C3: ='Data Sheet'!C41 -> 45291 | D3: ='Data Sheet'!D41 -> 45382 | E3: ='Data Sheet'!E41 -> 45473 | F3: ='Data Sheet'!F41 -> 45565 | G3: ='Data Sheet'!G41 -> 45657 | H3: ='Data Sheet'!H41 -> 45747 | I3: ='Data Sheet'!I41 -> 45838 | ... K3: ='Data Sheet'!K41 -> 46022
A4: Sales | B4: ='Data Sheet'!B42 -> 17774.47 | C4: ='Data Sheet'!C42 -> 17195.24 | D4: ='Data Sheet'!D42 -> 17037.8 | E4: ='Data Sheet'!E42 -> 17777.81 | F4: ='Data Sheet'!F42 -> 19990.36 | G4: ='Data Sheet'!G42 -> 18790.17 | H4: ='Data Sheet'!H42 -> 18765 | I4: ='Data Sheet'!I42 -> 21494.79 | ... K4: ='Data Sheet'!K42 -> 20047.3
A5: Expenses | B5: ='Data Sheet'!B43 -> 11320.23 | C5: ='Data Sheet'!C43 -> 10985.01 | D5: ='Data Sheet'!D43 -> 10735.73 | E5: ='Data Sheet'!E43 -> 11232.97 | F5: ='Data Sheet'!F43 -> 13438.28 | G5: ='Data Sheet'!G43 -> 12428.27 | H5: ='Data Sheet'!H43 -> 12245.61 | I5: ='Data Sheet'!I43 -> 14678.32 | ... K5: ='Data Sheet'!K43 -> 13164.78
A6: Operating Profit | B6: ='Data Sheet'!B50 -> 6454.24 | C6: ='Data Sheet'!C50 -> 6210.23 | D6: ='Data Sheet'!D50 -> 6302.07 | E6: ='Data Sheet'!E50 -> 6544.84 | F6: ='Data Sheet'!F50 -> 6552.08 | G6: ='Data Sheet'!G50 -> 6361.9 | H6: ='Data Sheet'!H50 -> 6519.39 | I6: ='Data Sheet'!I50 -> 6816.47 | ... K6: ='Data Sheet'!K50 -> 6882.52
A7: Other Income | B7: ='Data Sheet'!B44 -> 673.5 | C7: ='Data Sheet'!C44 -> 820.26 | D7: ='Data Sheet'!D44 -> 868 | E7: ='Data Sheet'!E44 -> 771.13 | F7: ='Data Sheet'!F44 -> 690.31 | G7: ='Data Sheet'!G44 -> 803.4 | H7: ='Data Sheet'!H44 -> 15391.28 | I7: ='Data Sheet'!I44 -> 750.97 | ... K7: ='Data Sheet'!K44 -> 321.85
A8: Depreciation | B8: ='Data Sheet'!B45 -> 453.04 | C8: ='Data Sheet'!C45 -> 384.04 | D8: ='Data Sheet'!D45 -> 385.09 | E8: ='Data Sheet'!E45 -> 403.13 | F8: ='Data Sheet'!F45 -> 416.18 | G8: ='Data Sheet'!G45 -> 415.98 | H8: ='Data Sheet'!H45 -> 411.03 | I8: ='Data Sheet'!I45 -> 422.96 | ... K8: ='Data Sheet'!K45 -> 430.82
A9: Interest | B9: ='Data Sheet'!B46 -> 9.87 | C9: ='Data Sheet'!C46 -> 11.94 | D9: ='Data Sheet'!D46 -> 10.72 | E9: ='Data Sheet'!E46 -> 9.6 | F9: ='Data Sheet'!F46 -> 14.73 | G9: ='Data Sheet'!G46 -> 9.82 | H9: ='Data Sheet'!H46 -> 10.91 | I9: ='Data Sheet'!I46 -> 16.47 | ... K9: ='Data Sheet'!K46 -> 19.47
A10: Profit before tax | B10: ='Data Sheet'!B47 -> 6664.83 | C10: ='Data Sheet'!C47 -> 6634.51 | D10: ='Data Sheet'!D47 -> 6774.26 | E10: ='Data Sheet'!E47 -> 6903.24 | F10: ='Data Sheet'!F47 -> 6811.48 | G10: ='Data Sheet'!G47 -> 6739.5 | H10: ='Data Sheet'!H47 -> 21488.73 | I10: ='Data Sheet'!I47 -> 7128.01 | ... K10: ='Data Sheet'!K47 -> 6754.08
A11: Tax | B11: ='Data Sheet'!B48 -> 1700.31 | C11: ='Data Sheet'!C48 -> 1227.99 | D11: ='Data Sheet'!D48 -> 1583.55 | E11: ='Data Sheet'!E48 -> 1726.25 | F11: ='Data Sheet'!F48 -> 1757.05 | G11: ='Data Sheet'!G48 -> 1726.32 | H11: ='Data Sheet'!H48 -> 1680.85 | I11: ='Data Sheet'!I48 -> 1784.6 | ... K11: ='Data Sheet'!K48 -> 1735.63
A12: Net profit | B12: ='Data Sheet'!B49 -> 4898.07 | C12: ='Data Sheet'!C49 -> 5335.23 | D12: ='Data Sheet'!D49 -> 5120.55 | E12: ='Data Sheet'!E49 -> 5091.59 | F12: ='Data Sheet'!F49 -> 4992.87 | G12: ='Data Sheet'!G49 -> 4934.8 | H12: ='Data Sheet'!H49 -> 19727.37 | I12: ='Data Sheet'!I49 -> 5244.2 | ... K12: ='Data Sheet'!K49 -> 4931.19
A14: OPM | B14: =IF(B4>0,B6/B4,"") -> 0.36311856 | C14: =IF(C4>0,C6/C4,"") -> 0.36115983 | D14: =IF(D4>0,D6/D4,"") -> 0.36988754 | E14: =IF(E4>0,E6/E4,"") -> 0.36814658 | F14: =IF(F4>0,F6/F4,"") -> 0.32776198 | G14: =IF(G4>0,G6/G4,"") -> 0.33857597 | H14: =IF(H4>0,H6/H4,"") -> 0.34742286 | I14: =IF(I4>0,I6/I4,"") -> 0.31712196 | ... K14: =IF(K4>0,K6/K4,"") -> 0.34331406

Sheet Balance Sheet
A1: ='Profit-Loss'!A1 -> ITC LTD | E1: =UPDATE | J1: SCREENER.IN
A3: Narration | B3: ='Data Sheet'!B56 -> 42460 | C3: ='Data Sheet'!C56 -> 42825 | D3: ='Data Sheet'!D56 -> 43190 | E3: ='Data Sheet'!E56 -> 43555 | F3: ='Data Sheet'!F56 -> 43921 | G3: ='Data Sheet'!G56 -> 44286 | H3: ='Data Sheet'!H56 -> 44651 | I3: ='Data Sheet'!I56 -> 45016 | ... K3: ='Data Sheet'!K56 -> 45747
A4: Equity Share Capital | B4: ='Data Sheet'!B57 -> 804.72 | C4: ='Data Sheet'!C57 -> 1214.74 | D4: ='Data Sheet'!D57 -> 1220.43 | E4: ='Data Sheet'!E57 -> 1225.86 | F4: ='Data Sheet'!F57 -> 1229.22 | G4: ='Data Sheet'!G57 -> 1230.88 | H4: ='Data Sheet'!H57 -> 1232.33 | I4: ='Data Sheet'!I57 -> 1242.8 | ... K4: ='Data Sheet'!K57 -> 1251.41
A5: Reserves | B5: ='Data Sheet'!B58 -> 41874.8 | C5: ='Data Sheet'!C58 -> 45198.19 | D5: ='Data Sheet'!D58 -> 51289.68 | E5: ='Data Sheet'!E58 -> 57915.01 | F5: ='Data Sheet'!F58 -> 64044.04 | G5: ='Data Sheet'!G58 -> 59116.46 | H5: ='Data Sheet'!H58 -> 61223.24 | I5: ='Data Sheet'!I58 -> 67912.46 | ... K5: ='Data Sheet'!K58 -> 68778.64
A6: Borrowings | B6: ='Data Sheet'!B59 -> 83.78 | C6: ='Data Sheet'!C59 -> 45.72 | D6: ='Data Sheet'!D59 -> 35.92 | E6: ='Data Sheet'!E59 -> 13.44 | F6: ='Data Sheet'!F59 -> 277.45 | G6: ='Data Sheet'!G59 -> 270.83 | H6: ='Data Sheet'!H59 -> 249.44 | I6: ='Data Sheet'!I59 -> 306.04 | ... K6: ='Data Sheet'!K59 -> 284.54
A7: Other Liabilities | B7: ='Data Sheet'!B60 -> 8888.04 | C7: ='Data Sheet'!C60 -> 9439.67 | D7: ='Data Sheet'!D60 -> 11694.85 | E7: ='Data Sheet'!E60 -> 12584.73 | F7: ='Data Sheet'!F60 -> 11760.04 | G7: ='Data Sheet'!G60 -> 13142.59 | H7: ='Data Sheet'!H60 -> 14491.01 | I7: ='Data Sheet'!I60 -> 16369.66 | ... K7: ='Data Sheet'!K60 -> 17688.11
A8: Total | B8: ='Data Sheet'!B61 -> 51651.34 | C8: ='Data Sheet'!C61 -> 55898.32 | D8: ='Data Sheet'!D61 -> 64240.88 | E8: ='Data Sheet'!E61 -> 71739.04 | F8: ='Data Sheet'!F61 -> 77310.75 | G8: ='Data Sheet'!G61 -> 73760.76 | H8: ='Data Sheet'!H61 -> 77196.02 | I8: ='Data Sheet'!I61 -> 85830.96 | ... K8: ='Data Sheet'!K61 -> 88002.7
A10: Net Block | B10: ='Data Sheet'!B62 -> 15106.63 | C10: ='Data Sheet'!C62 -> 15893.48 | D10: ='Data Sheet'!D62 -> 16523.96 | E10: ='Data Sheet'!E62 -> 19374.19 | F10: ='Data Sheet'!F62 -> 21713.34 | G10: ='Data Sheet'!G62 -> 23298.48 | H10: ='Data Sheet'!H62 -> 24231.59 | I10: ='Data Sheet'!I62 -> 25851.27 | ... K10: ='Data Sheet'!K62 -> 21954.85
A11: Capital Work in Progress | B11: ='Data Sheet'!B63 -> 2559.72 | C11: ='Data Sheet'!C63 -> 3729.89 | D11: ='Data Sheet'!D63 -> 5508.33 | E11: ='Data Sheet'!E63 -> 4136.42 | F11: ='Data Sheet'!F63 -> 3256.46 | G11: ='Data Sheet'!G63 -> 4011.29 | H11: ='Data Sheet'!H63 -> 3225.54 | I11: ='Data Sheet'!I63 -> 3003.3 | ... K11: ='Data Sheet'!K63 -> 1090.91
A12: Investments | B12: ='Data Sheet'!B64 -> 11747.59 | C12: ='Data Sheet'!C64 -> 17581.38 | D12: ='Data Sheet'!D64 -> 22052.86 | E12: ='Data Sheet'!E64 -> 25043.49 | F12: ='Data Sheet'!F64 -> 28663.35 | G12: ='Data Sheet'!G64 -> 24870.87 | H12: ='Data Sheet'!H64 -> 24841.01 | I12: ='Data Sheet'!I64 -> 29415.02 | ... K12: ='Data Sheet'!K64 -> 34719.82
A13: Other Assets | B13: ='Data Sheet'!B65 -> 22237.4 | C13: ='Data Sheet'!C65 -> 18693.57 | D13: ='Data Sheet'!D65 -> 20155.73 | E13: ='Data Sheet'!E65 -> 23184.94 | F13: ='Data Sheet'!F65 -> 23677.6 | G13: ='Data Sheet'!G65 -> 21580.12 | H13: ='Data Sheet'!H65 -> 24897.88 | I13: ='Data Sheet'!I65 -> 27561.37 | ... K13: ='Data Sheet'!K65 -> 30237.12
A14: Total | B14: ='Data Sheet'!B66 -> 51651.34 | C14: ='Data Sheet'!C66 -> 55898.32 | D14: ='Data Sheet'!D66 -> 64240.88 | E14: ='Data Sheet'!E66 -> 71739.04 | F14: ='Data Sheet'!F66 -> 77310.75 | G14: ='Data Sheet'!G66 -> 73760.76 | H14: ='Data Sheet'!H66 -> 77196.02 | I14: ='Data Sheet'!I66 -> 85830.96 | ... K14: ='Data Sheet'!K66 -> 88002.7
A16: Working Capital | B16: =B13-B7 -> 13349.36 | C16: =C13-C7 -> 9253.9 | D16: =D13-D7 -> 8460.88 | E16: =E13-E7 -> 10600.21 | F16: =F13-F7 -> 11917.56 | G16: =G13-G7 -> 8437.53 | H16: =H13-H7 -> 10406.87 | I16: =I13-I7 -> 11191.71 | ... K16: =K13-K7 -> 12549.01
A17: Debtors | B17: ='Data Sheet'!B67 -> 1917.18 | C17: ='Data Sheet'!C67 -> 2474.29 | D17: ='Data Sheet'!D67 -> 2682.29 | E17: ='Data Sheet'!E67 -> 4035.28 | F17: ='Data Sheet'!F67 -> 2562.48 | G17: ='Data Sheet'!G67 -> 2501.7 | H17: ='Data Sheet'!H67 -> 2461.9 | I17: ='Data Sheet'!I67 -> 2956.17 | ... K17: ='Data Sheet'!K67 -> 4719.67
A18: Inventory | B18: ='Data Sheet'!B68 -> 9062.1 | C18: ='Data Sheet'!C68 -> 8116.1 | D18: ='Data Sheet'!D68 -> 7495.09 | E18: ='Data Sheet'!E68 -> 7859.56 | F18: ='Data Sheet'!F68 -> 8879.33 | G18: ='Data Sheet'!G68 -> 10397.16 | H18: ='Data Sheet'!H68 -> 10864.15 | I18: ='Data Sheet'!I68 -> 11771.16 | ... K18: ='Data Sheet'!K68 -> 15637.56
A20: Debtor Days | B20: =IF('Profit-Loss'!B4>0,'Balance Sheet'!B17/('Profit-Loss'!B4/365),0) -> 17.854892 | C20: =IF('Profit-Loss'!C4>0,'Balance Sheet'!C17/('Profit-Loss'!C4/365),0) -> 21.116823 | D20: =IF('Profit-Loss'!D4>0,'Balance Sheet'!D17/('Profit-Loss'!D4/365),0) -> 22.53302 | E20: =IF('Profit-Loss'!E4>0,'Balance Sheet'!E17/('Profit-Loss'!E4/365),0) -> 30.469383 | F20: =IF('Profit-Loss'!F4>0,'Balance Sheet'!F17/('Profit-Loss'!F4/365),0) -> 18.938019 | G20: =IF('Profit-Loss'!G4>0,'Balance Sheet'!G17/('Profit-Loss'!G4/365),0) -> 18.537714 | H20: =IF('Profit-Loss'!H4>0,'Balance Sheet'!H17/('Profit-Loss'!H4/365),0) -> 14.817385 | I20: =IF('Profit-Loss'!I4>0,'Balance Sheet'!I17/('Profit-Loss'!I4/365),0) -> 15.214563 | ... K20: =IF('Profit-Loss'!K4>0,'Balance Sheet'!K17/('Profit-Loss'!K4/365),0) -> 22.870462
A21: Inventory Turnover | B21: =IF('Balance Sheet'!B18>0,'Profit-Loss'!B4/'Balance Sheet'!B18,0) -> 4.3248364 | C21: =IF('Balance Sheet'!C18>0,'Profit-Loss'!C4/'Balance Sheet'!C18,0) -> 5.2694767 | D21: =IF('Balance Sheet'!D18>0,'Profit-Loss'!D4/'Balance Sheet'!D18,0) -> 5.7969871 | E21: =IF('Balance Sheet'!E18>0,'Profit-Loss'!E4/'Balance Sheet'!E18,0) -> 6.1504181 | F21: =IF('Balance Sheet'!F18>0,'Profit-Loss'!F4/'Balance Sheet'!F18,0) -> 5.5620976 | G21: =IF('Balance Sheet'!G18>0,'Profit-Loss'!G4/'Balance Sheet'!G18,0) -> 4.737587 | H21: =IF('Balance Sheet'!H18>0,'Profit-Loss'!H4/'Balance Sheet'!H18,0) -> 5.5820787 | I21: =IF('Balance Sheet'!I18>0,'Profit-Loss'!I4/'Balance Sheet'!I18,0) -> 6.0248123 | ... K21: =IF('Balance Sheet'!K18>0,'Profit-Loss'!K4/'Balance Sheet'!K18,0) -> 4.8168218
A23: Return on Equity | B23: =IF(SUM('Balance Sheet'!B4:B5)>0,'Profit-Loss'!B12/SUM('Balance Sheet'!B4:B5),"") -> 0.21894459 | C23: =IF(SUM('Balance Sheet'!C4:C5)>0,'Profit-Loss'!C12/SUM('Balance Sheet'!C4:C5),"") -> 0.22169339 | D23: =IF(SUM('Balance Sheet'!D4:D5)>0,'Profit-Loss'!D12/SUM('Balance Sheet'!D4:D5),"") -> 0.21464819 | E23: =IF(SUM('Balance Sheet'!E4:E5)>0,'Profit-Loss'!E12/SUM('Balance Sheet'!E4:E5),"") -> 0.21292095 | F23: =IF(SUM('Balance Sheet'!F4:F5)>0,'Profit-Loss'!F12/SUM('Balance Sheet'!F4:F5),"") -> 0.23449465 | G23: =IF(SUM('Balance Sheet'!G4:G5)>0,'Profit-Loss'!G12/SUM('Balance Sheet'!G4:G5),"") -> 0.21809064 | H23: =IF(SUM('Balance Sheet'!H4:H5)>0,'Profit-Loss'!H12/SUM('Balance Sheet'!H4:H5),"") -> 0.24405605 | I23: =IF(SUM('Balance Sheet'!I4:I5)>0,'Profit-Loss'!I12/SUM('Balance Sheet'!I4:I5),"") -> 0.27751555 | ... K23: =IF(SUM('Balance Sheet'!K4:K5)>0,'Profit-Loss'!K12/SUM('Balance Sheet'!K4:K5),"") -> 0.49616743
A24: Return on Capital Emp | C24: =IF((B4+B5+B6+C4+C5+C6)>0,('Profit-Loss'!C10+'Profit-Loss'!C9)*2/(B4+B5+B6+C4+C5+C6),"") -> 0.36034518 | D24: =IF((C4+C5+C6+D4+D5+D6)>0,('Profit-Loss'!D10+'Profit-Loss'!D9)*2/(C4+C5+C6+D4+D5+D6),"") -> 0.35400589 | E24: =IF((D4+D5+D6+E4+E5+E6)>0,('Profit-Loss'!E10+'Profit-Loss'!E9)*2/(D4+D5+D6+E4+E5+E6),"") -> 0.34415688 | F24: =IF((E4+E5+E6+F4+F5+F6)>0,('Profit-Loss'!F10+'Profit-Loss'!F9)*2/(E4+E5+E6+F4+F5+F6),"") -> 0.32261652 | G24: =IF((F4+F5+F6+G4+G5+G6)>0,('Profit-Loss'!G10+'Profit-Loss'!G9)*2/(F4+F5+F6+G4+G5+G6),"") -> 0.28527066 | H24: =IF((G4+G5+G6+H4+H5+H6)>0,('Profit-Loss'!H10+'Profit-Loss'!H9)*2/(G4+G5+G6+H4+H5+H6),"") -> 0.33733253 | I24: =IF((H4+H5+H6+I4+I5+I6)>0,('Profit-Loss'!I10+'Profit-Loss'!I9)*2/(H4+H5+H6+I4+I5+I6),"") -> 0.39333609 | J24: =IF((I4+I5+I6+J4+J5+J6)>0,('Profit-Loss'!J10+'Profit-Loss'!J9)*2/(I4+I5+I6+J4+J5+J6),"") -> 0.37429273 | K24: =IF((J4+J5+J6+K4+K5+K6)>0,('Profit-Loss'!K10+'Profit-Loss'!K9)*2/(J4+J5+J6+K4+K5+K6),"") -> 0.57864605
A26: book value | E26: =SUM(E4:E5) -> 59140.87 | F26: =SUM(F4:F5) -> 65273.26 | G26: =SUM(G4:G5) -> 60347.34 | H26: =SUM(H4:H5) -> 62455.57 | I26: =SUM(I4:I5) -> 69155.26 | J26: =SUM(J4:J5) -> 74507 | K26: =SUM(K4:K5) -> 70030.05

Sheet Cash Flow
A1: ='Balance Sheet'!A1 -> ITC LTD | E1: =UPDATE | J1: SCREENER.IN
A3: Narration | B3: ='Data Sheet'!B81 -> 42460 | C3: ='Data Sheet'!C81 -> 42825 | D3: ='Data Sheet'!D81 -> 43190 | E3: ='Data Sheet'!E81 -> 43555 | F3: ='Data Sheet'!F81 -> 43921 | G3: ='Data Sheet'!G81 -> 44286 | H3: ='Data Sheet'!H81 -> 44651 | I3: ='Data Sheet'!I81 -> 45016 | ... K3: ='Data Sheet'!K81 -> 45747
A4: Cash from Operating Activity | B4: ='Data Sheet'!B82 -> 9799.04 | C4: ='Data Sheet'!C82 -> 10627.31 | D4: ='Data Sheet'!D82 -> 13169.4 | E4: ='Data Sheet'!E82 -> 12583.41 | F4: ='Data Sheet'!F82 -> 14689.66 | G4: ='Data Sheet'!G82 -> 12526.97 | H4: ='Data Sheet'!H82 -> 15775.51 | I4: ='Data Sheet'!I82 -> 18877.55 | ... K4: ='Data Sheet'!K82 -> 17627.04
A5: Cash from Investing Activity | B5: ='Data Sheet'!B83 -> -3920.73 | C5: ='Data Sheet'!C83 -> -3250.93 | D5: ='Data Sheet'!D83 -> -7113.89 | E5: ='Data Sheet'!E83 -> -5545.68 | F5: ='Data Sheet'!F83 -> -6174.02 | G5: ='Data Sheet'!G83 -> 5739.98 | H5: ='Data Sheet'!H83 -> -2238.49 | I5: ='Data Sheet'!I83 -> -5732.29 | ... K5: ='Data Sheet'!K83 -> -563.84
A6: Cash from Financing Activity | B6: ='Data Sheet'!B84 -> -5612.52 | C6: ='Data Sheet'!C84 -> -7301.03 | D6: ='Data Sheet'!D84 -> -6221.13 | E6: ='Data Sheet'!E84 -> -6868.64 | F6: ='Data Sheet'!F84 -> -8181.48 | G6: ='Data Sheet'!G84 -> -18633.83 | H6: ='Data Sheet'!H84 -> -13580.5 | I6: ='Data Sheet'!I84 -> -13006.03 | ... K6: ='Data Sheet'!K84 -> -17037.4
A7: Net Cash Flow | B7: ='Data Sheet'!B85 -> 265.79 | C7: ='Data Sheet'!C85 -> 75.35 | D7: ='Data Sheet'!D85 -> -165.62 | E7: ='Data Sheet'!E85 -> 169.09 | F7: ='Data Sheet'!F85 -> 334.16 | G7: ='Data Sheet'!G85 -> -366.88 | H7: ='Data Sheet'!H85 -> -43.48 | I7: ='Data Sheet'!I85 -> 139.23 | ... K7: ='Data Sheet'!K85 -> 25.8
